Workbook

Sheet Sheet2

Sheet Sheet5
A1: Calculated Field
A2: Solve Order | B2: Field | C2: Formula
A3: 1 | B3: variance Amount | C3: ='Actual JAN 2025'-'Prior Yr JAN 2024'
A4: 2 | B4: Variance % | C4: ='variance Amount'/'Prior Yr JAN 2024'
A5: 3 | B5: % Dist | C5: ='variance Amount'
A6: 4 | B6: % Distri | C6: ='variance Amount'
A8: Calculated Item
A9: Solve Order | B9: Item | C9: Formula
A12: Note: | B12: When a cell is updated by more than one formula,
B13: the value is set by the formula with the last solve order.
B15: To change the solve order for multiple calculated items or fields,
B16: on the Options tab, in the Calculations group, click Fields, Items, & Sets, and then click Solve Order.

Sheet Sheet3
A1: Mapping | B1: Social Costs / Benef | J1: Mapping | K1: Intercompany Charges
A3: Row Labels | B3: Sum of Prior Yr JAN 2024 | C3: Sum of Actual JAN 2025 | D3: Sum of variance Amount | E3: Sum of Variance % | F3: Sum of % Dist | J3: Row Labels | K3: Sum of Prior Yr JAN 2024 | L3: Sum of Actual JAN 2025 | M3: Sum of variance Amount | N3: Sum of Variance % | O3: Sum of % Distri
A4: Worker's Comp | B4: 31922.11 | C4: 101727.91 | D4: 69805.8 | E4: 2.1867539 | F4: 0.41066951 | J4: Service | K4: -34272.95 | L4: 93964.8 | M4: 128237.75 | N4: -3.7416607 | O4: 0.85912979
A5: Medical Insurance | B5: 868009.69 | C5: 932160.43 | D5: 64150.74 | E5: 0.073905557 | F5: 0.37740063 | J5: Marketing | K5: -12474.98 | L5: 10152.05 | M5: 22627.03 | N5: -1.8137929 | O5: 0.15158996
A6: Social Security | B6: 599108.84 | C6: 627186.19 | D6: 28077.35 | E6: 0.046865191 | F6: 0.16517985 | J6: General & Admin | K6: 141083.7 | L6: 145273.49 | M6: 4189.79 | N6: 0.029697194 | O6: 0.02806953
A7: Pension (401k/PK) | B7: 432097.78 | C7: 438806.18 | D7: 6708.4 | E7: 0.01552519 | F7: 0.039465708 | J7: Logistics&Purch. Costs | K7: -5651.42 | L7: -11441.29 | M7: -5789.87 | N7: 1.0244983 | O7: -0.038789278
A8: Unemployment Premium | B8: 2030.26 | C8: 3127.23 | D8: 1096.97 | E8: 0.54031011 | F8: 0.0064535057 | J8: Grand Total | K8: 88684.35 | L8: 237949.05 | M8: 149264.7 | N8: 1.6831008 | O8: 1
A9: Other Social Costs | B9: 1958.01 | C9: 2099.23 | D9: 141.22 | E9: 0.072124249 | F9: 0.00083080128
A10: Absence/Vacation Exp | D10: 0 | E10: #DIV/0! | F10: 0
A11: Grand Total | B11: 1935126.7 | C11: 2105107.2 | D11: 169980.48 | E11: 0.087839458 | F11: 1
A26: Row Labels | B26: Sum of Prior Yr JAN 2024 | C26: Sum of Actual JAN 2025 | D26: Sum of variance Amount | E26: Sum of Variance % | F26: Sum of % Dist
A27: Base Compensation | B27: 7239250.1 | C27: 7681633.2 | D27: 442383.04 | E27: 0.061108959 | F27: 0.14604074
A28: Social Costs / Benef | B28: 1935126.7 | C28: 2095862.1 | D28: 160735.43 | E28: 0.083061967 | F28: 0.053062436
A29: Vehicle Costs | B29: 1563515.9 | C29: 2213367.3 | D29: 649851.42 | E29: 0.41563467 | F29: 0.21453079
A30: Commissions / Other | B30: 1096611.1 | C30: 1403785.6 | D30: 307174.53 | E30: 0.28011256 | F30: 0.10140533
A31: Travel and Entertain | B31: 888787.61 | C31: 1242131.9 | D31: 353344.26 | E31: 0.39755759 | F31: 0.11664701
A32: Maintenance and Util | B32: 541614 | C32: 537374.28 | D32: -4239.72 | E32: -0.0078279365 | F32: -0.0013996284
A33: Promotion and Advert | B33: 313130.56 | C33: 354853.78 | D33: 41723.22 | E33: 0.13324544 | F33: 0.013773788
A34: Intercompany Charges | B34: 177368.7 | C34: 475898.1 | D34: 298529.4 | E34: 1.6831008 | F34: 0.098551372
A35: Telecommunications | B35: 168601.46 | C35: 171151.32 | D35: 2549.86 | E35: 0.015123594 | F35: 0.00084176701
A36: Depreciation | B36: 160816.62 | C36: 149204.16 | D36: -11612.46 | E36: -0.072209328 | F36: -0.0038335382
A37: Consultants & Other | B37: 145808.98 | C37: 177819.32 | D37: 32010.34 | E37: 0.21953614 | F37: 0.010567344
A38: Agent Commissions / Dealer Programs | B38: 96293.33 | C38: 129585 | D38: 33291.67 | E38: 0.34573184 | F38: 0.01099034
... A43: Hardware / Software | B43: 30894.98 | C43: 83630.3 | D43: 52735.32 | E43: 1.706922 | F43: 0.017409133
A44: R&D Materials & Sub Contractors | D44: 0 | E44: #DIV/0! | F44: 0
A45: Other Period Expense | B45: -1093526 | C45: -805616.66 | D45: 287909.36 | E45: -0.26328533 | F45: 0.095045454
A46: Grand Total | B46: 13518298 | C46: 16547474 | D46: 3029175.5 | E46: 0.22407964 | F46: 1

Sheet Sheet1
A1: Company Code | B1: Profit Center | C1: Cost Element | D1: CE Name | E1: Functional area | F1: Actual JAN 2025 | G1: Prior Yr JAN 2024 | H1: Mapping
A2: Mettler-Toledo, LLC - MTI | B2: MTMO-US | C2: TOP | D2: Total Period Expense | E2: Logistics&Purch. Costs | F2: 141242.3 | G2: 101408.46 | H2: =IFERROR(VLOOKUP(C2,Sheet4!B:C,2,0),"")
A3: Mettler-Toledo, LLC - MTI | B3: MTMO-US | C3: TOP | D3: Total Period Expense | E3: Service | F3: 6853813.3 | G3: 5883162 | H3: =IFERROR(VLOOKUP(C3,Sheet4!B:C,2,0),"")
A4: Mettler-Toledo, LLC - MTI | B4: MTMO-US | C4: TOP | D4: Total Period Expense | E4: Marketing | F4: 6537197.4 | G4: 5513403.8 | H4: =IFERROR(VLOOKUP(C4,Sheet4!B:C,2,0),"")
A5: Mettler-Toledo, LLC - MTI | B5: MTMO-US | C5: TOP | D5: Total Period Expense | E5: Promotion | F5: 139994.01 | G5: 99431.43 | H5: =IFERROR(VLOOKUP(C5,Sheet4!B:C,2,0),"")
A6: Mettler-Toledo, LLC - MTI | B6: MTMO-US | C6: TOP | D6: Total Period Expense | E6: General & Admin | F6: 792457.79 | G6: 908120.09 | H6: =IFERROR(VLOOKUP(C6,Sheet4!B:C,2,0),"")
A7: Mettler-Toledo, LLC - MTI | B7: MTMO-US | C7: TOP_00 | D7: Total PEX ex-Bonus/C | E7: Logistics&Purch. Costs | F7: 129785.7 | G7: 103990.79 | H7: =IFERROR(VLOOKUP(C7,Sheet4!B:C,2,0),"")
A8: Mettler-Toledo, LLC - MTI | B8: MTMO-US | C8: TOP_00 | D8: Total PEX ex-Bonus/C | E8: Service | F8: 6420246.6 | G8: 5665948.7 | H8: =IFERROR(VLOOKUP(C8,Sheet4!B:C,2,0),"")
A9: Mettler-Toledo, LLC - MTI | B9: MTMO-US | C9: TOP_00 | D9: Total PEX ex-Bonus/C | E9: Marketing | F9: 5159571.1 | G9: 4488875.5 | H9: =IFERROR(VLOOKUP(C9,Sheet4!B:C,2,0),"")
A10: Mettler-Toledo, LLC - MTI | B10: MTMO-US | C10: TOP_00 | D10: Total PEX ex-Bonus/C | E10: Promotion | F10: 139994.01 | G10: 99431.43 | H10: =IFERROR(VLOOKUP(C10,Sheet4!B:C,2,0),"")
A11: Mettler-Toledo, LLC - MTI | B11: MTMO-US | C11: TOP_00 | D11: Total PEX ex-Bonus/C | E11: General & Admin | F11: 757550.04 | G11: 895376.05 | H11: =IFERROR(VLOOKUP(C11,Sheet4!B:C,2,0),"")
A12: Mettler-Toledo, LLC - MTI | B12: MTMO-US | C12: 7210100 | D12: Building Rent | E12: Logistics&Purch. Costs | F12: 2780.41 | H12: =IFERROR(VLOOKUP(C12,Sheet4!B:C,2,0),"")
A13: Mettler-Toledo, LLC - MTI | B13: MTMO-US | C13: 7210100 | D13: Building Rent | E13: Service | F13: 50616.63 | G13: 23867.78 | H13: =IFERROR(VLOOKUP(C13,Sheet4!B:C,2,0),"")
A14: Mettler-Toledo, LLC - MTI | B14: MTMO-US | C14: 7210100 | D14: Building Rent | E14: Marketing | F14: 85371.63 | G14: 90234.69 | H14: =IFERROR(VLOOKUP(C14,Sheet4!B:C,2,0),"")
A15: Mettler-Toledo, LLC - MTI | B15: MTMO-US | C15: 7210100 | D15: Building Rent | E15: General & Admin | F15: -4966.96 | H15: =IFERROR(VLOOKUP(C15,Sheet4!B:C,2,0),"")
A16: Mettler-Toledo, LLC - MTI | B16: MTMO-US | C16: 7210110 | D16: Mov. Assets Rent | E16: General & Admin | F16: 4966.96 | H16: =IFERROR(VLOOKUP(C16,Sheet4!B:C,2,0),"")
A17: Mettler-Toledo, LLC - MTI | B17: MTMO-US | C17: 7210111 | D17: MaintBuilding-Leased | E17: Logistics&Purch. Costs | F17: -2871.71 | H17: =IFERROR(VLOOKUP(C17,Sheet4!B:C,2,0),"")
A18: Mettler-Toledo, LLC - MTI | B18: MTMO-US | C18: 7210111 | D18: MaintBuilding-Leased | E18: Service | F18: -2426.86 | G18: 3048.2 | H18: =IFERROR(VLOOKUP(C18,Sheet4!B:C,2,0),"")
A19: Mettler-Toledo, LLC - MTI | B19: MTMO-US | C19: 7210111 | D19: MaintBuilding-Leased | E19: Marketing | F19: 1836.22 | G19: 332.95 | H19: =IFERROR(VLOOKUP(C19,Sheet4!B:C,2,0),"")
A20: Mettler-Toledo, LLC - MTI | B20: MTMO-US | C20: 7210111 | D20: MaintBuilding-Leased | E20: General & Admin | F20: 77936.72 | G20: 98177.04 | H20: =IFERROR(VLOOKUP(C20,Sheet4!B:C,2,0),"")
A21: Mettler-Toledo, LLC - MTI | B21: MTMO-US | C21: 7210112 | D21: Utility-Elect-Leased | E21: Service | F21: 1235.79 | G21: 1035.57 | H21: =IFERROR(VLOOKUP(C21,Sheet4!B:C,2,0),"")
A22: Mettler-Toledo, LLC - MTI | B22: MTMO-US | C22: 7210112 | D22: Utility-Elect-Leased | E22: Marketing | F22: 94.3 | G22: 79.33 | H22: =IFERROR(VLOOKUP(C22,Sheet4!B:C,2,0),"")
A23: Mettler-Toledo, LLC - MTI | B23: MTMO-US | C23: 7210113 | D23: Utility-NatGas-Lease | E23: Service | F23: 101.29 | G23: 126.35 | H23: =IFERROR(VLOOKUP(C23,Sheet4!B:C,2,0),"")
A24: Mettler-Toledo, LLC - MTI | B24: MTMO-US | C24: 7210114 | D24: Util-WatSewer-Lease | E24: Service | F24: 104.74 | G24: 172.52 | H24: =IFERROR(VLOOKUP(C24,Sheet4!B:C,2,0),"")
A25: Mettler-Toledo, LLC - MTI | B25: MTMO-US | C25: 7210115 | D25: Utility-Other-Leased | E25: Service | F25: 690 | G25: 294.15 | H25: =IFERROR(VLOOKUP(C25,Sheet4!B:C,2,0),"")
A26: Mettler-Toledo, LLC - MTI | B26: MTMO-US | C26: 7210116 | D26: RealEstateTax-Leased | E26: Service | H26: =IFERROR(VLOOKUP(C26,Sheet4!B:C,2,0),"")
A27: Mettler-Toledo, LLC - MTI | B27: MTMO-US | C27: 7210117 | D27: PropertyInsure-Lease | E27: Service | H27: =IFERROR(VLOOKUP(C27,Sheet4!B:C,2,0),"")
A28: Mettler-Toledo, LLC - MTI | B28: MTMO-US | C28: 7210117 | D28: PropertyInsure-Lease | E28: Marketing | H28: =IFERROR(VLOOKUP(C28,Sheet4!B:C,2,0),"")
A29: Mettler-Toledo, LLC - MTI | B29: MTMO-US | C29: 7210118 | D29: ST LsEx-RealEst-Leas | E29: Service | F29: 4443.17 | G29: 5556.77 | H29: =IFERROR(VLOOKUP(C29,Sheet4!B:C,2,0),"")
A30: Mettler-Toledo, LLC - MTI | B30: MTMO-US | C30: 7210118 | D30: ST LsEx-RealEst-Leas | E30: Marketing | F30: 1152.08 | G30: 1289.45 | H30: =IFERROR(VLOOKUP(C30,Sheet4!B:C,2,0),"")
A31: Mettler-Toledo, LLC - MTI | B31: MTMO-US | C31: 7210119 | D31: LseNotCap-RealEstExp | E31: Service | F31: 15251.33 | G31: 11886.71 | H31: =IFERROR(VLOOKUP(C31,Sheet4!B:C,2,0),"")
A32: Mettler-Toledo, LLC - MTI | B32: MTMO-US | C32: 7210119 | D32: LseNotCap-RealEstExp | E32: Marketing | F32: 2866.7 | G32: 2898.72 | H32: =IFERROR(VLOOKUP(C32,Sheet4!B:C,2,0),"")
A33: Mettler-Toledo, LLC - MTI | B33: MTMO-US | C33: 7210119 | D33: LseNotCap-RealEstExp | E33: General & Admin | G33: 90 | H33: =IFERROR(VLOOKUP(C33,Sheet4!B:C,2,0),"")
A34: Mettler-Toledo, LLC - MTI | B34: MTMO-US | C34: 7210200 | D34: Maintenance Building | E34: Service | F34: 3661.88 | G34: 2540.57 | H34: =IFERROR(VLOOKUP(C34,Sheet4!B:C,2,0),"")
A35: Mettler-Toledo, LLC - MTI | B35: MTMO-US | C35: 7210200 | D35: Maintenance Building | E35: Marketing | F35: 524.84 | G35: 1763.27 | H35: =IFERROR(VLOOKUP(C35,Sheet4!B:C,2,0),"")
A36: Mettler-Toledo, LLC - MTI | B36: MTMO-US | C36: 7210200 | D36: Maintenance Building | E36: General & Admin | F36: 12024.4 | G36: 9108.38 | H36: =IFERROR(VLOOKUP(C36,Sheet4!B:C,2,0),"")
A37: Mettler-Toledo, LLC - MTI | B37: MTMO-US | C37: 7210410 | D37: Utilities - Electric | E37: Service | F37: 1793.86 | G37: 4827.26 | H37: =IFERROR(VLOOKUP(C37,Sheet4!B:C,2,0),"")
A38: Mettler-Toledo, LLC - MTI | B38: MTMO-US | C38: 7210410 | D38: Utilities - Electric | E38: Marketing | F38: 172.73 | G38: 755.87 | H38: =IFERROR(VLOOKUP(C38,Sheet4!B:C,2,0),"")
A39: Mettler-Toledo, LLC - MTI | B39: MTMO-US | C39: 7210420 | D39: Utilities - Nat. Gas | E39: Service | F39: 302.98 | G39: 407.03 | H39: =IFERROR(VLOOKUP(C39,Sheet4!B:C,2,0),"")
A40: Mettler-Toledo, LLC - MTI | B40: MTMO-US | C40: 7210420 | D40: Utilities - Nat. Gas | E40: Marketing | F40: 56.78 | G40: 29.14 | H40: =IFERROR(VLOOKUP(C40,Sheet4!B:C,2,0),"")
...

Sheet Sheet4
B1: Cost Element | C1: Head | D1: Cost Element
B2: 7100050 | C2: Base Compensation | D2: 7100050
B3: 7100100 | C3: Base Compensation | D3: 7100100
B4: 7100125 | C4: Base Compensation | D4: 7100125
B5: 7100150 | C5: Base Compensation | D5: 7100150
B6: 7100200 | C6: Base Compensation | D6: 7100200
B7: 7100250 | C7: Base Compensation | D7: 7100250
B8: 7100260 | C8: Base Compensation | D8: 7100260
B9: 7100300 | C9: Base Compensation | D9: 7100300
B10: 7100305 | C10: Base Compensation | D10: 7100305
B11: 7100310 | C11: Base Compensation | D11: 7100310
B12: 7100315 | C12: Base Compensation | D12: 7100315
B13: 7100320 | C13: Base Compensation | D13: 7100320
... B134: 7200200 | C134: Agent Commissions / Dealer Programs | D134: 7200200
B135: ZZZZZZ1 | C135: Agent Commissions / Dealer Programs | D135: ZZZZZZ1
B136: 7210100 | C136: Maintenance and Util | D136: 7210100
B137: 7210110 | C137: Maintenance and Util | D137: 7210110
B138: 7210111 | C138: Maintenance and Util | D138: 7210111
B139: 7210112 | C139: Maintenance and Util | D139: 7210112
B140: 7210113 | C140: Maintenance and Util | D140: 7210113
B141: 7210114 | C141: Maintenance and Util | D141: 7210114
B142: 7210115 | C142: Maintenance and Util | D142: 7210115
B143: 7210116 | C143: Maintenance and Util | D143: 7210116
B144: 7210117 | C144: Maintenance and Util | D144: 7210117
B145: 7210118 | C145: Maintenance and Util | D145: 7210118
B146: 7210119 | C146: Maintenance and Util | D146: 7210119
B147: 7210200 | C147: Maintenance and Util | D147: 7210200
... B287: 7299950 | C287: Other Period Expense | D287: 7299950
B288: ZZZZZZ3 | C288: Other Period Expense | D288: ZZZZZZ3
B289: ZZZZZZ4 | C289: Other Period Expense | D289: ZZZZZZ4
B290: ZZZZZ11 | C290: Other Period Expense | D290: ZZZZZ11
B291: ZZZZZZ2 | C291: Other Period Expense | D291: ZZZZZZ2
B292: ZZZZZZ5 | C292: Other Period Expense | D292: ZZZZZZ5
B293: ZZZZZZ6 | C293: Other Period Expense | D293: ZZZZZZ6
B294: ZZZZZZ7 | C294: Other Period Expense | D294: ZZZZZZ7
B295: 7293100 | C295: IC Charges-BlueOcean | D295: 7293100
B296: ZZZZZ12 | C296: Other Period Expense | D296: ZZZZZ12
B297: 7230055 | C297: Vehicle Costs | D297: 7230055
B298: 7299020 | C298: Other Period Expense | D298: 7299020
B299: 7299271 | C299: Other Period Expense | D299: 7299271
...
