Workbook

Sheet Oct
A1: View | E1: Periodic
A2: Value | E2: <Entity Curr Total>
A3: Intercompany | E3: [ICP Top]
A4: Custom 3 | E4: [None]
A5: Custom 4 | E5: [None]
G6: MTMS | H6: MTMS | I6: AM-HUB | J6: AM-HUB | K6: MTAC | L6: MTAC | M6: MTII-GF | N6: MTII-GF | O6: MTG-CF | P6: MTG-CF | Q6: MT-TR | R6: MT-TR | S6: MT-B | T6: MT-B | U6: MT-NL | V6: MT-NL | W6: MTANA | X6: MTANA | Y6: MT-MEC ex-UA | Z6: MT-MEC ex-UA | AA6: MT-CDN | AB6: MT-CDN | AC6: MTMO-US | AD6: MTMO-US | AE6: MTMO-China (CNY) | AF6: MTMO-China (CNY) | AG6: MT-MY | AH6: MT-MY | AI6: MTAP-SER | AJ6: MTAP-SER | AK6: MTGF-AP | AL6: MTGF-AP | AM6: AP-HUB | AN6: AP-HUB | AO6: MT-ID | AP6: MT-ID | AQ6: MT-CIS (CONS.) | AR6: MT-CIS (CONS.) | AS6: MT-TW | AT6: MT-TW | AU6: MT-JP | AV6: MT-JP | AW6: MT-KR | AX6: MT-KR | AY6: MTIN | AZ6: MTIN | BA6: MT-AUS/NZ | BB6: MT-AUS/NZ | BC6: Eagle-US | BD6: Eagle-US | BE6: Eagle EMEA | BF6: Eagle EMEA | BG6: MT-UK | BH6: MT-UK | BI6: CSN | BJ6: CSN | BK6: MTA | BL6: MTA | BM6: TRUS | BN6: TRUS | BO6: OHUS | BP6: OHUS | BQ6: MTAC-IRL | BR6: MTAC-IRL | BS6: OHHLT | BT6: OHHLT | BU6: OHCS (Cons CNY) | BV6: OHCS (Cons CNY) | BW6: India IMSG | BX6: India IMSG | BY6: MTTS | BZ6: MTTS | CA6: MT-D | CB6: MT-D | CC6: MT-A | CD6: MT-A | CE6: MT-CH | CF6: MT-CH | CG6: MTPOChina (CNY) | CH6: MTPOChina (CNY) | CI6: MT-F | CJ6: MT-F | CK6: MT-UA | CL6: MT-UA | CM6: WeighTec | CN6: WeighTec | CO6: MT-Nordic | CP6: MT-Nordic | CQ6: MTI-HF | CR6: MTI-HF | CS6: MTII | CT6: MTII | CU6: MTREH | CV6: MTREH | CW6: MTFUS2 | CX6: MTFUS2 | CY6: MTBDS | CZ6: MTBDS | DA6: MTIF | DB6: MTIF | DC6: MTCI-2 | DD6: MTCI-2 | DE6: MTTJ (Cons.) | DF6: MTTJ (Cons.) | DG6: MTAH | DH6: MTAH | DI6: MTO-CH | DJ6: MTO-CH | DK6: MTNH-1 | DL6: MTNH-1 | DM6: MTNH-2 | DN6: MTNH-2 | DO6: MTMD | DP6: MTMD | DQ6: MTHFR | DR6: MTHFR | DS6: MTFINUK | DT6: MTFINUK | DU6: MTH | DV6: MTH | DW6: MTHLLC | DX6: MTHLLC | DY6: MICROWA | DZ6: MICROWA | EA6: EU-HUB | EB6: EU-HUB | EC6: MTPL SBC | ED6: MTPL SBC | EE6: MT-PR | EF6: MT-PR | EG6: India GBSI | EH6: India GBSI | EI6: SLUK | EJ6: SLUK | EK6: SLXR | EL6: SLXR | EM6: MTGA | EN6: MTGA | EO6: PI-D | EP6: PI-D | EQ6: MTPRO-US | ER6: MTPRO-US | ES6: PendoTECH | ET6: PendoTECH | EU6: THOR | EV6: THOR | EW6: RAININ | EX6: RAININ | EY6: BIOTIX (Cons.) | EZ6: BIOTIX (Cons.) | FA6: MTPRO | FB6: MTPRO | FC6: MT-SG | FD6: MT-SG | FE6: PIUS PO | FF6: PIUS PO | FG6: PIUS MO | FH6: PIUS MO | FI6: MT-MX | FJ6: MT-MX | FK6: MT-BR | FL6: MT-BR | FM6: MT-SI | FN6: MT-SI | FO6: MT-I | FP6: MT-I | FQ6: MT-E | FR6: MT-E | FS6: MT-TH | FT6: MT-TH | FU6: MT-VN | FV6: MT-VN | FW6: VOL-EU (Cons) | FX6: VOL-EU (Cons)
G7: 115.106 | H7: 115.106 | I7: 115.107 | J7: 115.107 | K7: 140.1042 | L7: 140.1042 | M7: 185.1085 | N7: 185.1085 | O7: 190.2185 | P7: 190.2185 | Q7: 211_EUR.2111 | R7: 211_EUR.2111 | S7: 270.2130 | T7: 270.2130 | U7: 270.3000 | V7: 270.3000 | W7: 295.2186 | X7: 295.2186 | Y7: 299_USD.299_EUR | Z7: 299_USD.299_EUR | AA7: 355.1012 | AB7: 355.1012 | AC7: 355.1021 | AD7: 355.1021 | AE7: 511_USD.511 | AF7: 511_USD.511 | AG7: 562.5161 | AH7: 562.5161 | AI7: 562.5162 | AJ7: 562.5162 | AK7: 929.5085 | AL7: 929.5085 | AM7: AP_Hub.5011 | AN7: AP_Hub.5011 | AO7: Geo_ID.5183 | AP7: Geo_ID.5183 | AQ7: GMC_ASIA.250 | AR7: GMC_ASIA.250 | AS7: GMC_ASIA.5025 | AT7: GMC_ASIA.5025 | AU7: GMC_ASIA.5031 | AV7: GMC_ASIA.5031 | AW7: GMC_ASIA.5141 | AX7: GMC_ASIA.5141 | AY7: GMC_ASIA.5151 | AZ7: GMC_ASIA.5151 | BA7: GMC_ASIA.524 | BB7: GMC_ASIA.524 | BC7: GMC_EA_EMEA.1034 | BD7: GMC_EA_EMEA.1034 | BE7: GMC_EA_EMEA.2034 | BF7: GMC_EA_EMEA.2034 | BG7: GMC_EURO_MO.2072 | BH7: GMC_EURO_MO.2072 | BI7: GMC_IND.2035 | BJ7: GMC_IND.2035 | BK7: GMC_IND.2095 | BL7: GMC_IND.2095 | BM7: GMC_Lab.1024 | BN7: GMC_Lab.1024 | BO7: GMC_Lab.1027 | BP7: GMC_Lab.1027 | BQ7: GMC_Lab.2042 | BR7: GMC_Lab.2042 | BS7: GMC_Lab.2096 | BT7: GMC_Lab.2096 | BU7: GMC_Lab.512 | BV7: GMC_Lab.512 | BW7: GMC_Lab.5155 | BX7: GMC_Lab.5155 | BY7: GMC_Lab.5157 | BZ7: GMC_Lab.5157 | CA7: GMC_MOCentral_EU.2090 | CB7: GMC_MOCentral_EU.2090 | CC7: GMC_MOCentral_EU.2160 | CD7: GMC_MOCentral_EU.2160 | CE7: GMC_MOCentral_EU.2175 | CF7: GMC_MOCentral_EU.2175 | CG7: GMC_MOPOChina.515 | CH7: GMC_MOPOChina.515 | CI7: GMC_MT_F.2140 | CJ7: GMC_MT_F.2140 | CK7: GMC_MT_UA.2511_USD | CL7: GMC_MT_UA.2511_USD | CM7: GMC_MTIC_LAB_CHF.2181 | CN7: GMC_MTIC_LAB_CHF.2181 | CO7: GMC_NRegion_EU.232 | CP7: GMC_NRegion_EU.232 | CQ7: GMC_OTH.1025 | CR7: GMC_OTH.1025 | CS7: GMC_OTH.1029 | CT7: GMC_OTH.1029 | CU7: GMC_OTH.1064 | CV7: GMC_OTH.1064 | CW7: GMC_OTH.1067 | CX7: GMC_OTH.1067 | CY7: GMC_OTH.1069 | CZ7: GMC_OTH.1069 | DA7: GMC_OTH.1092 | DB7: GMC_OTH.1092 | DC7: GMC_OTH.1096 | DD7: GMC_OTH.1096 | DE7: GMC_OTH.159 | DF7: GMC_OTH.159 | DG7: GMC_OTH.2008 | DH7: GMC_OTH.2008 | DI7: GMC_OTH.2010 | DJ7: GMC_OTH.2010 | DK7: GMC_OTH.2036 | DL7: GMC_OTH.2036 | DM7: GMC_OTH.2037 | DN7: GMC_OTH.2037 | DO7: GMC_OTH.2098 | DP7: GMC_OTH.2098 | DQ7: GMC_OTH.2148 | DR7: GMC_OTH.2148 | DS7: GMC_OTH.2165 | DT7: GMC_OTH.2165 | DU7: GMC_OTH.2171 | DV7: GMC_OTH.2171 | DW7: GMC_OTH.2173 | DX7: GMC_OTH.2173 | DY7: GMC_OTH.2177 | DZ7: GMC_OTH.2177 | EA7: GMC_OTH.2178 | EB7: GMC_OTH.2178 | EC7: GMC_OTH.297_PL | ED7: GMC_OTH.297_PL | EE7: GMC_OTH.5026 | EF7: GMC_OTH.5026 | EG7: GMC_OTH.5153 | EH7: GMC_OTH.5153 | EI7: GMC_PI.2076 | EJ7: GMC_PI.2076 | EK7: GMC_PI.2077 | EL7: GMC_PI.2077 | EM7: GMC_PI.2093 | EN7: GMC_PI.2093 | EO7: GMC_PI.2094 | EP7: GMC_PI.2094 | EQ7: GMC_Pro.1022 | ER7: GMC_Pro.1022 | ES7: GMC_Pro.1044 | ET7: GMC_Pro.1044 | EU7: GMC_Pro.1045 | EV7: GMC_Pro.1045 | EW7: GMC_Pro.1046 | EX7: GMC_Pro.1046 | EY7: GMC_Pro.156 | EZ7: GMC_Pro.156 | FA7: GMC_Pro.2187 | FB7: GMC_Pro.2187 | FC7: GMC_SG_ID_SGD.5181 | FD7: GMC_SG_ID_SGD.5181 | FE7: GMC_SL_HI_CIV.1036 | FF7: GMC_SL_HI_CIV.1036 | FG7: GMC_SL_HI_CIV.1038 | FH7: GMC_SL_HI_CIV.1038 | FI7: GMC_SRegion_EU_MX.1031 | FJ7: GMC_SRegion_EU_MX.1031 | FK7: GMC_SRegion_EU_MX.1241 | FL7: GMC_SRegion_EU_MX.1241 | FM7: GMC_SRegion_EU_MX.2060 | FN7: GMC_SRegion_EU_MX.2060 | FO7: GMC_SRegion_EU_MX.2200 | FP7: GMC_SRegion_EU_MX.2200 | FQ7: GMC_SRegion_EU_MX.2241 | FR7: GMC_SRegion_EU_MX.2241 | FS7: GMC_TH_VN_THB.5191 | FT7: GMC_TH_VN_THB.5191 | FU7: GMC_TH_VN_THB.5193 | FV7: GMC_TH_VN_THB.5193 | FW7: Tax_Vol_OHLog.204 | FX7: Tax_Vol_OHLog.204
G8: Actual | H8: =+G8 -> Actual | I8: =+H8 -> Actual | J8: =+I8 -> Actual | K8: =+J8 -> Actual | L8: =+K8 -> Actual | M8: =+L8 -> Actual | N8: =+M8 -> Actual | O8: =+N8 -> Actual | ... FX8: =+FW8 -> Actual
G9: Oct | H9: =+G9 -> Oct | I9: =+H9 -> Oct | J9: =+I9 -> Oct | K9: =+J9 -> Oct | L9: =+K9 -> Oct | M9: =+L9 -> Oct | N9: =+M9 -> Oct | O9: =+N9 -> Oct | ... FX9: =+FW9 -> Oct
G10: 2025 | H10: 2024 | I10: 2025 | J10: 2024 | K10: 2025 | L10: 2024 | M10: 2025 | N10: 2024 | O10: 2025 | P10: 2024 | Q10: 2025 | R10: 2024 | S10: 2025 | T10: 2024 | U10: 2025 | V10: 2024 | W10: 2025 | X10: 2024 | Y10: 2025 | Z10: 2024 | AA10: 2025 | AB10: 2024 | AC10: 2025 | AD10: 2024 | AE10: 2025 | AF10: 2024 | AG10: 2025 | AH10: 2024 | AI10: 2025 | AJ10: 2024 | AK10: 2025 | AL10: 2024 | AM10: 2025 | AN10: 2024 | AO10: 2025 | AP10: 2024 | AQ10: 2025 | AR10: 2024 | AS10: 2025 | AT10: 2024 | AU10: 2025 | AV10: 2024 | AW10: 2025 | AX10: 2024 | AY10: 2025 | AZ10: 2024 | BA10: 2025 | BB10: 2024 | BC10: 2025 | BD10: 2024 | BE10: 2025 | BF10: 2024 | BG10: 2025 | BH10: 2024 | BI10: 2025 | BJ10: 2024 | BK10: 2025 | BL10: 2024 | BM10: 2025 | BN10: 2024 | BO10: 2025 | BP10: 2024 | BQ10: 2025 | BR10: 2024 | BS10: 2025 | BT10: 2024 | BU10: 2025 | BV10: 2024 | BW10: 2025 | BX10: 2024 | BY10: 2025 | BZ10: 2024 | CA10: 2025 | CB10: 2024 | CC10: 2025 | CD10: 2024 | CE10: 2025 | CF10: 2024 | CG10: 2025 | CH10: 2024 | CI10: 2025 | CJ10: 2024 | CK10: 2025 | CL10: 2024 | CM10: 2025 | CN10: 2024 | CO10: 2025 | CP10: 2024 | CQ10: 2025 | CR10: 2024 | CS10: 2025 | CT10: 2024 | CU10: 2025 | CV10: 2024 | CW10: 2025 | CX10: 2024 | CY10: 2025 | CZ10: 2024 | DA10: 2025 | DB10: 2024 | DC10: 2025 | DD10: 2024 | DE10: 2025 | DF10: 2024 | DG10: 2025 | DH10: 2024 | DI10: 2025 | DJ10: 2024 | DK10: 2025 | DL10: 2024 | DM10: 2025 | DN10: 2024 | DO10: 2025 | DP10: 2024 | DQ10: 2025 | DR10: 2024 | DS10: 2025 | DT10: 2024 | DU10: 2025 | DV10: 2024 | DW10: 2025 | DX10: 2024 | DY10: 2025 | DZ10: 2024 | EA10: 2025 | EB10: 2024 | EC10: 2025 | ED10: 2024 | EE10: 2025 | EF10: 2024 | EG10: 2025 | EH10: 2024 | EI10: 2025 | EJ10: 2024 | EK10: 2025 | EL10: 2024 | EM10: 2025 | EN10: 2024 | EO10: 2025 | EP10: 2024 | EQ10: 2025 | ER10: 2024 | ES10: 2025 | ET10: 2024 | EU10: 2025 | EV10: 2024 | EW10: 2025 | EX10: 2024 | EY10: 2025 | EZ10: 2024 | FA10: 2025 | FB10: 2024 | FC10: 2025 | FD10: 2024 | FE10: 2025 | FF10: 2024 | FG10: 2025 | FH10: 2024 | FI10: 2025 | FJ10: 2024 | FK10: 2025 | FL10: 2024 | FM10: 2025 | FN10: 2024 | FO10: 2025 | FP10: 2024 | FQ10: 2025 | FR10: 2024 | FS10: 2025 | FT10: 2024 | FU10: 2025 | FV10: 2024 | FW10: 2025 | FX10: 2024
A11: Account | B11: Product/Service | C11: Division | D11: DPC | E11: Custom2 | G11: =VLOOKUP(G6,Currency!$B:$E,4,FALSE) -> USD | H11: =VLOOKUP(H6,Currency!$B:$E,4,FALSE) -> USD | I11: =VLOOKUP(I6,Currency!$B:$E,4,FALSE) -> USD | J11: =VLOOKUP(J6,Currency!$B:$E,4,FALSE) -> USD | K11: =VLOOKUP(K6,Currency!$B:$E,4,FALSE) -> USD | L11: =VLOOKUP(L6,Currency!$B:$E,4,FALSE) -> USD | M11: =VLOOKUP(M6,Currency!$B:$E,4,FALSE) -> CHF | N11: =VLOOKUP(N6,Currency!$B:$E,4,FALSE) -> CHF | ... FX11: =VLOOKUP(FX6,Currency!$B:$E,4,FALSE) -> EUR
A12: o_sale_IC | B12: PRODUCT | C12: Lab | D12: Labtec | E12: [None] | F12: Sales IC | G12: 0 | H12: 0 | I12: -49372.265 | J12: 6280.7479 | K12: 0 | L12: 0 | M12: 0 | N12: 0 | O12: 0 | P12: 0 | Q12: 0 | R12: 0 | S12: 0 | T12: 0 | U12: -31.15304 | V12: 7.98568 | W12: -117.4478 | X12: 25.40552 | Y12: 0 | Z12: 0 | AA12: 0 | AB12: 0 | AC12: 0 | AD12: 0 | AE12: 0 | AF12: 0 | AG12: 0 | AH12: 0 | AI12: 0 | AJ12: 0 | AK12: 0 | AL12: 0 | AM12: -367484.21 | AN12: 41054.54 | AO12: 0 | AP12: 934.41 | AQ12: 0 | AR12: 0 | AS12: 0 | AT12: 0 | AU12: 0 | AV12: 0 | AW12: 0 | AX12: 0 | AY12: -9134.7992 | AZ12: 11089.537 | BA12: 0 | BB12: 0 | BC12: 0 | BD12: 0 | BE12: 0 | BF12: 0 | BG12: 0 | BH12: 0 | BI12: 0 | BJ12: 0 | BK12: -774.49131 | BL12: 177.55526 | BM12: -898.92622 | BN12: 120.63665 | BO12: 0 | BP12: 0 | BQ12: 0 | BR12: 0 | BS12: 0 | BT12: 0 | BU12: -275.08662 | BV12: 17.90378 | BW12: 0 | BX12: 0 | BY12: 0 | BZ12: 0 | CA12: 6.12574 | CB12: 0 | CC12: 3.411 | CD12: 0 | CE12: 0 | CF12: 0 | CG12: -540240.54 | CH12: 57657.856 | CI12: -220.86617 | CJ12: 6.27925 | CK12: 0 | CL12: 0 | CM12: -92538.901 | CN12: 13873.181 | CO12: 0 | CP12: 0 | CQ12: 0 | CR12: 0 | CS12: 0 | CT12: 0 | CU12: 0 | CV12: 0 | CW12: 0 | CX12: 0 | CY12: 0 | CZ12: 0 | DA12: 0 | DB12: 0 | DC12: 0 | DD12: 0 | DE12: -2.54198 | DF12: 0 | DG12: 0 | DH12: 0 | DI12: 0 | DJ12: 0 | DK12: 0 | DL12: 0 | DM12: 0 | DN12: 0 | DO12: 0 | DP12: 0 | DQ12: 0 | DR12: 0 | DS12: 0 | DT12: 0 | DU12: 0 | DV12: 0 | DW12: 0 | DX12: 0 | DY12: 0 | DZ12: 0 | EA12: -110136.37 | EB12: 16583.639 | EC12: 0 | ED12: 0 | EE12: 0 | EF12: 0 | EG12: 0 | EH12: 0 | EI12: -0.26661 | EJ12: 0.11188 | EK12: 0 | EL12: 2.41436 | EM12: -5.14206 | EN12: 0.24486 | EO12: 0 | EP12: 0 | EQ12: 0 | ER12: 0 | ES12: 0 | ET12: 0 | EU12: 0 | EV12: 0 | EW12: -6.40032 | EX12: 2.08791 | EY12: 0 | EZ12: 0 | FA12: 0 | FB12: 0 | FC12: 0 | FD12: 0 | FE12: -9.36 | FF12: 0 | FG12: 0 | FH12: 0 | FI12: 0 | FJ12: 0 | FK12: -13.292667 | FL12: 1.69925 | FM12: 0 | FN12: 0 | FO12: -3.409 | FP12: 0 | FQ12: -0.03286 | FR12: 0 | FS12: 0 | FT12: 0 | FU12: 0 | FV12: 0 | FW12: 0.1381 | FX12: 0
A13: o_sale_IC | B13: PRODUCT | C13: Lab | D13: Pipettes | E13: [None] | F13: Sales IC | G13: 0 | H13: 0 | I13: -0.04333 | J13: 0.00972 | K13: 0 | L13: 0 | M13: 0 | N13: 0 | O13: 0 | P13: 0 | Q13: 0 | R13: 0 | S13: 0 | T13: 0 | U13: -16.48256 | V13: 0 | W13: 0 | X13: 5.33414 | Y13: 0 | Z13: 0 | AA13: 0 | AB13: 0 | AC13: 0 | AD13: 0 | AE13: 0 | AF13: 0 | AG13: 0 | AH13: 0 | AI13: 0 | AJ13: 0 | AK13: 0 | AL13: 0 | AM13: -80148.456 | AN13: 8113.2702 | AO13: 0 | AP13: 0 | AQ13: 0 | AR13: 0 | AS13: 0 | AT13: 0 | AU13: 0 | AV13: 0 | AW13: 0 | AX13: 0 | AY13: 0 | AZ13: 0 | BA13: 0 | BB13: 0 | BC13: 0 | BD13: 0 | BE13: 0 | BF13: 0 | BG13: 0 | BH13: 0 | BI13: 0 | BJ13: 0 | BK13: 0 | BL13: 0 | BM13: 0 | BN13: 0 | BO13: 0 | BP13: 0 | BQ13: 0 | BR13: 0 | BS13: 0 | BT13: 0 | BU13: 0 | BV13: 0 | BW13: 0 | BX13: 0 | BY13: 0 | BZ13: 0 | CA13: 0 | CB13: 0 | CC13: 0 | CD13: 0 | CE13: 0 | CF13: 0 | CG13: -47121.653 | CH13: 4475.2331 | CI13: 0 | CJ13: 0 | CK13: 0 | CL13: 0 | CM13: -583.19916 | CN13: 65.54185 | CO13: 0 | CP13: 0 | CQ13: 0 | CR13: 0 | CS13: 0 | CT13: 0 | CU13: 0 | CV13: 0 | CW13: 0 | CX13: 0 | CY13: 0 | CZ13: 0 | DA13: 0 | DB13: 0 | DC13: 0 | DD13: 0 | DE13: 0 | DF13: 0 | DG13: 0 | DH13: 0 | DI13: 0 | DJ13: 0 | DK13: 0 | DL13: 0 | DM13: 0 | DN13: 0 | DO13: 0 | DP13: 0 | DQ13: 0 | DR13: 0 | DS13: 0 | DT13: 0 | DU13: 0 | DV13: 0 | DW13: 0 | DX13: 0 | DY13: 0 | DZ13: 0 | EA13: -14990.648 | EB13: 1652.5471 | EC13: 0 | ED13: 0 | EE13: 0 | EF13: 0 | EG13: 0 | EH13: 0 | EI13: 0 | EJ13: 0 | EK13: 0 | EL13: 0 | EM13: 0 | EN13: 0 | EO13: 0 | EP13: 0 | EQ13: 0 | ER13: 0 | ES13: 0 | ET13: 0 | EU13: 0 | EV13: 0 | EW13: -27743.871 | EX13: 3333.6427 | EY13: -2565.0582 | EZ13: 485.57538 | FA13: 0 | FB13: 0 | FC13: 0 | FD13: 0 | FE13: 0 | FF13: 0 | FG13: 0 | FH13: 0 | FI13: 0 | FJ13: 0 | FK13: -53.5423 | FL13: 0 | FM13: 0 | FN13: 0 | FO13: 0 | FP13: 0 | FQ13: 0 | FR13: 0 | FS13: 0 | FT13: 0 | FU13: 0 | FV13: 0 | FW13: 0 | FX13: 0
A14: o_sale_IC | B14: PRODUCT | C14: Lab | D14: Biotix | E14: [None] | F14: Sales IC | G14: 0 | H14: 0 | I14: 0 | J14: 0 | K14: 0 | L14: 0 | M14: 0 | N14: 0 | O14: 0 | P14: 0 | Q14: 0 | R14: 0 | S14: 0 | T14: 0 | U14: 0 | V14: 0 | W14: 0 | X14: 0 | Y14: 0 | Z14: 0 | AA14: 0 | AB14: 0 | AC14: 0 | AD14: 0 | AE14: 0 | AF14: 0 | AG14: 0 | AH14: 0 | AI14: 0 | AJ14: 0 | AK14: 0 | AL14: 0 | AM14: -192.09128 | AN14: 0 | AO14: 0 | AP14: 0 | AQ14: 0 | AR14: 0 | AS14: 0 | AT14: 0 | AU14: 0 | AV14: 0 | AW14: 0 | AX14: 0 | AY14: 0 | AZ14: 0 | BA14: 0 | BB14: 0 | BC14: 0 | BD14: 0 | BE14: 0 | BF14: 0 | BG14: 0 | BH14: 0 | BI14: 0 | BJ14: 0 | BK14: 0 | BL14: 0 | BM14: 0 | BN14: 0 | BO14: 0 | BP14: 0 | BQ14: 0 | BR14: 0 | BS14: 0 | BT14: 0 | BU14: 0 | BV14: 0 | BW14: 0 | BX14: 0 | BY14: 0 | BZ14: 0 | CA14: 0 | CB14: 0 | CC14: 0 | CD14: 0 | CE14: 0 | CF14: 0 | CG14: -227.26054 | CH14: 0 | CI14: 0 | CJ14: 0 | CK14: 0 | CL14: 0 | CM14: 0 | CN14: 0 | CO14: 0 | CP14: 0 | CQ14: 0 | CR14: 0 | CS14: 0 | CT14: 0 | CU14: 0 | CV14: 0 | CW14: 0 | CX14: 0 | CY14: 0 | CZ14: 0 | DA14: 0 | DB14: 0 | DC14: 0 | DD14: 0 | DE14: 0 | DF14: 0 | DG14: 0 | DH14: 0 | DI14: 0 | DJ14: 0 | DK14: 0 | DL14: 0 | DM14: 0 | DN14: 0 | DO14: 0 | DP14: 0 | DQ14: 0 | DR14: 0 | DS14: 0 | DT14: 0 | DU14: 0 | DV14: 0 | DW14: 0 | DX14: 0 | DY14: 0 | DZ14: 0 | EA14: 0 | EB14: 0 | EC14: 0 | ED14: 0 | EE14: 0 | EF14: 0 | EG14: 0 | EH14: 0 | EI14: 0 | EJ14: 0 | EK14: 0 | EL14: 0 | EM14: 0 | EN14: 0 | EO14: 0 | EP14: 0 | EQ14: 0 | ER14: 0 | ES14: 0 | ET14: 0 | EU14: 0 | EV14: 0 | EW14: -28.6206 | EX14: 0 | EY14: -80.482 | EZ14: 0 | FA14: 0 | FB14: 0 | FC14: 0 | FD14: 0 | FE14: 0 | FF14: 0 | FG14: 0 | FH14: 0 | FI14: 0 | FJ14: 0 | FK14: 0 | FL14: 0 | FM14: 0 | FN14: 0 | FO14: 0 | FP14: 0 | FQ14: 0 | FR14: 0 | FS14: 0 | FT14: 0 | FU14: 0 | FV14: 0 | FW14: 0 | FX14: 0
A15: o_sale_IC | B15: PRODUCT | C15: Lab | D15: ANA | E15: [None] | F15: Sales IC | G15: 0 | H15: 0 | I15: -33106.32 | J15: 4481.1906 | K15: 0 | L15: 0 | M15: 0 | N15: 0 | O15: 0 | P15: 0 | Q15: 0 | R15: 0 | S15: -0.10656 | T15: 0 | U15: -37.06703 | V15: 4.91364 | W15: -88221.132 | X15: 13084.834 | Y15: 0 | Z15: 0 | AA15: 0 | AB15: 0 | AC15: 0 | AD15: 0 | AE15: 0 | AF15: 0 | AG15: 0 | AH15: 0 | AI15: 0 | AJ15: 0 | AK15: 0 | AL15: 0 | AM15: -96941.066 | AN15: 11082.382 | AO15: -22317.112 | AP15: 84903.906 | AQ15: 0 | AR15: 0 | AS15: 0 | AT15: 0 | AU15: 0 | AV15: 0 | AW15: 0 | AX15: 0 | AY15: -129.1248 | AZ15: 1526.5394 | BA15: 0 | BB15: 0 | BC15: 0 | BD15: 0 | BE15: 0 | BF15: 0 | BG15: -0.01553 | BH15: 0 | BI15: 0 | BJ15: 0 | BK15: 0 | BL15: 0 | BM15: -33.60157 | BN15: 2.18506 | BO15: 0 | BP15: 0 | BQ15: 0 | BR15: 0 | BS15: 0 | BT15: 0 | BU15: 0 | BV15: 0 | BW15: 0 | BX15: 0 | BY15: 0 | BZ15: 0 | CA15: 0 | CB15: 0 | CC15: 0 | CD15: 0 | CE15: 0 | CF15: 0 | CG15: -134981.48 | CH15: 15894.56 | CI15: 1.422 | CJ15: -6.861 | CK15: 0 | CL15: 0 | CM15: -12076.055 | CN15: 1393.6343 | CO15: 0 | CP15: 0 | CQ15: 0 | CR15: 0 | CS15: 0 | CT15: 0 | CU15: 0 | CV15: 0 | CW15: 0 | CX15: 0 | CY15: 0 | CZ15: 0 | DA15: 0 | DB15: 0 | DC15: 0 | DD15: 0 | DE15: 0 | DF15: 0 | DG15: 0 | DH15: 0 | DI15: 0 | DJ15: 0 | DK15: 0 | DL15: 0 | DM15: 0 | DN15: 0 | DO15: 0 | DP15: 0 | DQ15: 0 | DR15: 0 | DS15: 0 | DT15: 0 | DU15: 0 | DV15: 0 | DW15: 0 | DX15: 0 | DY15: 0 | DZ15: 0 | EA15: -127259.58 | EB15: 17082.733 | EC15: 0 | ED15: 0 | EE15: 0 | EF15: 0 | EG15: 0 | EH15: 0 | EI15: 0 | EJ15: 0 | EK15: 0 | EL15: 0 | EM15: 0 | EN15: 0 | EO15: 0 | EP15: 0 | EQ15: 0 | ER15: 0 | ES15: 0 | ET15: 0 | EU15: -1815.0895 | EV15: 241.99454 | EW15: 0 | EX15: 0 | EY15: -83.88883 | EZ15: 0 | FA15: -12344.893 | FB15: 1478.83 | FC15: -3.84138 | FD15: 0 | FE15: 0 | FF15: 0 | FG15: 0 | FH15: 0 | FI15: 0 | FJ15: 0 | FK15: 0 | FL15: 6.66797 | FM15: 0 | FN15: 0 | FO15: 0 | FP15: 0 | FQ15: 0 | FR15: 0 | FS15: -235.2767 | FT15: 0 | FU15: 0 | FV15: 0 | FW15: 1.81826 | FX15: -0.41823
A16: o_sale_IC | B16: PRODUCT | C16: Lab | D16: Ohaus | E16: [None] | F16: Sales IC | G16: 0 | H16: 0 | I16: -34871.669 | J16: 3837.1614 | K16: 0 | L16: 0 | M16: 0 | N16: 0 | O16: 0 | P16: 0 | Q16: 0 | R16: 0 | S16: 0 | T16: 0 | U16: 0 | V16: 0 | W16: 0 | X16: 0 | Y16: 0 | Z16: 0 | AA16: 0 | AB16: 0 | AC16: 0 | AD16: 0 | AE16: 0 | AF16: 0 | AG16: 0 | AH16: 0 | AI16: 0 | AJ16: 0 | AK16: 0 | AL16: 0 | AM16: -274813.01 | AN16: 27468.855 | AO16: 0 | AP16: 0 | AQ16: 0 | AR16: 0 | AS16: 0 | AT16: 0 | AU16: 0 | AV16: 0 | AW16: 0 | AX16: 0 | AY16: 0 | AZ16: 0 | BA16: 0 | BB16: 0 | BC16: 0 | BD16: 0 | BE16: 0 | BF16: 0 | BG16: 0 | BH16: 0 | BI16: 0 | BJ16: 0 | BK16: -101.37617 | BL16: 8.9462 | BM16: -2854.2095 | BN16: 286.62366 | BO16: 0 | BP16: 0 | BQ16: 0 | BR16: 0 | BS16: -2321.1877 | BT16: 212.6157 | BU16: -288889.32 | BV16: 29791.977 | BW16: 0 | BX16: 0 | BY16: 0 | BZ16: 0 | CA16: 0 | CB16: 0 | CC16: 0 | CD16: 0 | CE16: 0 | CF16: 0 | CG16: -77339.525 | CH16: 8079.1474 | CI16: 0 | CJ16: 0 | CK16: 0 | CL16: 0 | CM16: -2758.5542 | CN16: 386.3395 | CO16: 0 | CP16: 0 | CQ16: 0 | CR16: 0 | CS16: 0 | CT16: 0 | CU16: 0 | CV16: 0 | CW16: 0 | CX16: 0 | CY16: 0 | CZ16: 0 | DA16: 0 | DB16: 0 | DC16: 0 | DD16: 0 | DE16: 0 | DF16: 0 | DG16: 0 | DH16: 0 | DI16: 0 | DJ16: 0 | DK16: 0 | DL16: 0 | DM16: 0 | DN16: 0 | DO16: 0 | DP16: 0 | DQ16: 0 | DR16: 0 | DS16: 0 | DT16: 0 | DU16: 0 | DV16: 0 | DW16: 0 | DX16: 0 | DY16: 0 | DZ16: 0 | EA16: -14016.561 | EB16: 1766.8943 | EC16: 0 | ED16: 0 | EE16: 0 | EF16: 0 | EG16: 0 | EH16: 0 | EI16: 0 | EJ16: 0 | EK16: 0 | EL16: 0 | EM16: 0 | EN16: 0 | EO16: 0 | EP16: 0 | EQ16: 0 | ER16: 0 | ES16: 0 | ET16: 0 | EU16: 0 | EV16: 0 | EW16: 0 | EX16: 0 | EY16: 0 | EZ16: 0 | FA16: 0 | FB16: 0 | FC16: 0 | FD16: 0 | FE16: 0 | FF16: 0 | FG16: 0 | FH16: 0 | FI16: 0 | FJ16: 0 | FK16: 0 | FL16: 0 | FM16: 0 | FN16: 0 | FO16: 0 | FP16: 0 | FQ16: 0 | FR16: 0 | FS16: 0 | FT16: 0 | FU16: 0 | FV16: 0 | FW16: -1.858 | FX16: 0
A17: o_sale_IC | B17: PRODUCT | C17: Lab | D17: AutoChem | E17: [None] | F17: Sales IC | G17: 0 | H17: 0 | I17: -1.59625 | J17: 0.40364 | K17: -6413.0959 | L17: 839.33643 | M17: 0 | N17: 0 | O17: 0 | P17: 0 | Q17: 0 | R17: 0 | S17: 0 | T17: 0 | U17: -1.22429 | V17: 0.16126 | W17: -15389.142 | X17: 2265.7524 | Y17: 0 | Z17: 0 | AA17: 0 | AB17: 0 | AC17: 0 | AD17: 0 | AE17: 0 | AF17: 0 | AG17: 0 | AH17: 0 | AI17: 0 | AJ17: 0 | AK17: 0 | AL17: 0 | AM17: -128.6087 | AN17: 14.74717 | AO17: 0 | AP17: 0 | AQ17: 0 | AR17: 0 | AS17: 0 | AT17: 0 | AU17: 0 | AV17: 0 | AW17: 0 | AX17: 0 | AY17: -28173.794 | AZ17: 2560.1737 | BA17: 0 | BB17: 0 | BC17: 0 | BD17: 0 | BE17: 0 | BF17: 0 | BG17: 0 | BH17: 0 | BI17: 0 | BJ17: 0 | BK17: 0 | BL17: 0 | BM17: 0 | BN17: 0 | BO17: 0 | BP17: 0 | BQ17: -4376.4546 | BR17: 538.8 | BS17: 0 | BT17: 0 | BU17: 0 | BV17: 0 | BW17: 0 | BX17: 0 | BY17: 0 | BZ17: 0 | CA17: 0 | CB17: 0 | CC17: 0 | CD17: 0 | CE17: 0 | CF17: 0 | CG17: -125.66372 | CH17: 19.68798 | CI17: 0 | CJ17: 0 | CK17: 0 | CL17: 0 | CM17: -274.65799 | CN17: 23.10515 | CO17: 0 | CP17: 0 | CQ17: 0 | CR17: 0 | CS17: 0 | CT17: 0 | CU17: 0 | CV17: 0 | CW17: 0 | CX17: 0 | CY17: 0 | CZ17: 0 | DA17: 0 | DB17: 0 | DC17: 0 | DD17: 0 | DE17: 0 | DF17: 0 | DG17: 0 | DH17: 0 | DI17: 0 | DJ17: 0 | DK17: 0 | DL17: 0 | DM17: 0 | DN17: 0 | DO17: 0 | DP17: 0 | DQ17: 0 | DR17: 0 | DS17: 0 | DT17: 0 | DU17: 0 | DV17: 0 | DW17: 0 | DX17: 0 | DY17: 0 | DZ17: 0 | EA17: -20008.787 | EB17: 3375.6484 | EC17: 0 | ED17: 0 | EE17: 0 | EF17: 0 | EG17: 0 | EH17: 0 | EI17: 0 | EJ17: 0 | EK17: 0 | EL17: 0 | EM17: 0 | EN17: 0 | EO17: 0 | EP17: 0 | EQ17: 0 | ER17: 0 | ES17: 0 | ET17: 0 | EU17: -10338.348 | EV17: 1496.8466 | EW17: 0 | EX17: 0 | EY17: 0 | EZ17: 0 | FA17: -10.93881 | FB17: 2.4346 | FC17: 0 | FD17: 0 | FE17: 0 | FF17: 0 | FG17: 0 | FH17: 0 | FI17: 0 | FJ17: 0 | FK17: 0 | FL17: 0 | FM17: 0 | FN17: 0 | FO17: 0 | FP17: 0 | FQ17: 0 | FR17: 0 | FS17: 0 | FT17: 0 | FU17: 0 | FV17: 0 | FW17: 0 | FX17: 0
A18: o_sale_IC | B18: PRODUCT | C18: PRO | D18: PRO | E18: [None] | F18: Sales IC | G18: 0 | H18: 0 | I18: -58230.213 | J18: 5816.3948 | K18: 0 | L18: 0 | M18: 0 | N18: 0 | O18: 0 | P18: 0 | Q18: 0 | R18: 0 | S18: 0 | T18: 0 | U18: 0 | V18: 0 | W18: 0 | X18: 0 | Y18: 0 | Z18: 0 | AA18: 0 | AB18: 0 | AC18: 0 | AD18: 0 | AE18: 0 | AF18: 0 | AG18: 0 | AH18: 0 | AI18: 0 | AJ18: 0 | AK18: 0 | AL18: 0 | AM18: -89779.124 | AN18: 10433.483 | AO18: 0 | AP18: 0 | AQ18: 0 | AR18: 0 | AS18: 0 | AT18: 0 | AU18: 0 | AV18: 0 | AW18: 0 | AX18: 0 | AY18: -2726.8589 | AZ18: 12129.609 | BA18: 0 | BB18: 0 | BC18: 0 | BD18: 0 | BE18: 0 | BF18: 0 | BG18: 0 | BH18: 0 | BI18: 0 | BJ18: 0 | BK18: -1937.6542 | BL18: 334.56807 | BM18: 0 | BN18: 0 | BO18: 0 | BP18: 0 | BQ18: 0 | BR18: 0 | BS18: 0 | BT18: 0 | BU18: 0 | BV18: 0 | BW18: 0 | BX18: 0 | BY18: 0 | BZ18: 0 | CA18: 0 | CB18: 0 | CC18: 0 | CD18: 0 | CE18: 0 | CF18: 0 | CG18: -147897.94 | CH18: 16019.367 | CI18: 0 | CJ18: 0 | CK18: 0 | CL18: 0 | CM18: -2640.2544 | CN18: 329.08866 | CO18: 0 | CP18: 0 | CQ18: 0 | CR18: 0 | CS18: 0 | CT18: 0 | CU18: 0 | CV18: 0 | CW18: 0 | CX18: 0 | CY18: 0 | CZ18: 0 | DA18: 0 | DB18: 0 | DC18: 0 | DD18: 0 | DE18: -10068.012 | DF18: 441.02885 | DG18: 0 | DH18: 0 | DI18: 0 | DJ18: 0 | DK18: 0 | DL18: 0 | DM18: 0 | DN18: 0 | DO18: 0 | DP18: 0 | DQ18: 0 | DR18: 0 | DS18: 0 | DT18: 0 | DU18: 0 | DV18: 0 | DW18: 0 | DX18: 0 | DY18: 0 | DZ18: 0 | EA18: -114447.04 | EB18: 12797.2 | EC18: 0 | ED18: 0 | EE18: 0 | EF18: 0 | EG18: 0 | EH18: 0 | EI18: 0 | EJ18: 0 | EK18: 0 | EL18: 0 | EM18: 0 | EN18: 0 | EO18: 0 | EP18: 0 | EQ18: 0 | ER18: 0 | ES18: -350.97 | ET18: 0 | EU18: -36668.011 | EV18: 4531.8171 | EW18: 0 | EX18: 0 | EY18: 0 | EZ18: 0 | FA18: -90296.966 | FB18: 9641.3505 | FC18: 0 | FD18: 0 | FE18: 0 | FF18: 0 | FG18: 0 | FH18: 0 | FI18: 0 | FJ18: 0 | FK18: 0 | FL18: 9.80239 | FM18: 0 | FN18: 0 | FO18: 0 | FP18: 0 | FQ18: 0 | FR18: 0 | FS18: 0 | FT18: 0 | FU18: 0 | FV18: 0 | FW18: 0 | FX18: 0
A19: o_sale_IC | B19: PRODUCT | C19: Industrial | D19: Standard Industrial | E19: [None] | F19: Sales IC | G19: -10074.264 | H19: 1112.2018 | I19: -27857.446 | J19: 3020.6653 | K19: 0 | L19: 0 | M19: 0 | N19: 0 | O19: 0 | P19: 0 | Q19: 0 | R19: 0 | S19: 0 | T19: 0 | U19: -4.30052 | V19: -0.68289 | W19: -1205.1815 | X19: 122.17832 | Y19: 0 | Z19: 0 | AA19: 0 | AB19: 0 | AC19: 0 | AD19: 0 | AE19: 0 | AF19: 0 | AG19: 0 | AH19: 0 | AI19: 0 | AJ19: 0 | AK19: 0 | AL19: 0 | AM19: -179139.24 | AN19: 19809.487 | AO19: 0 | AP19: 0 | AQ19: 0 | AR19: 0 | AS19: 0 | AT19: 0 | AU19: 0 | AV19: 0 | AW19: 0 | AX19: 0 | AY19: 0 | AZ19: 0 | BA19: 0 | BB19: 0 | BC19: 0 | BD19: 0 | BE19: 0 | BF19: 0 | BG19: -1.7232 | BH19: 0 | BI19: 0 | BJ19: 0 | BK19: -38969.293 | BL19: 5292.5017 | BM19: 0 | BN19: 0 | BO19: 0 | BP19: 0 | BQ19: 0 | BR19: 0 | BS19: 0 | BT19: 0 | BU19: 0 | BV19: 0 | BW19: 0 | BX19: 0 | BY19: 0 | BZ19: 0 | CA19: 5.75542 | CB19: 0 | CC19: 0 | CD19: 0 | CE19: 0 | CF19: 0 | CG19: -429657.11 | CH19: 46875.688 | CI19: 0 | CJ19: 0 | CK19: 0 | CL19: 0 | CM19: -7567.9641 | CN19: 856.43606 | CO19: 0 | CP19: 0 | CQ19: 0 | CR19: 0 | CS19: 0 | CT19: 0 | CU19: 0 | CV19: 0 | CW19: 0 | CX19: 0 | CY19: 0 | CZ19: 0 | DA19: 0 | DB19: 0 | DC19: 0 | DD19: 0 | DE19: -1908.4659 | DF19: 184.30717 | DG19: 0 | DH19: 0 | DI19: 0 | DJ19: 0 | DK19: 0 | DL19: 0 | DM19: 0 | DN19: 0 | DO19: 0 | DP19: 0 | DQ19: 0 | DR19: 0 | DS19: 0 | DT19: 0 | DU19: 0 | DV19: 0 | DW19: 0 | DX19: 0 | DY19: 0 | DZ19: 0 | EA19: -32449.131 | EB19: 3152.5019 | EC19: 0 | ED19: 0 | EE19: 0 | EF19: 0 | EG19: 0 | EH19: 0 | EI19: -0.34692 | EJ19: 0 | EK19: 0 | EL19: 0 | EM19: -3.75046 | EN19: 3.61231 | EO19: 0 | EP19: 0 | EQ19: 0 | ER19: 0 | ES19: 0 | ET19: 0 | EU19: 0 | EV19: 0 | EW19: 0 | EX19: 0 | EY19: 0 | EZ19: 0 | FA19: 0 | FB19: 0 | FC19: 0 | FD19: 0 | FE19: -2.37518 | FF19: 0 | FG19: 0 | FH19: 0 | FI19: 0 | FJ19: 0 | FK19: 0 | FL19: 0.33974 | FM19: 0 | FN19: 0 | FO19: 0 | FP19: -5.1375 | FQ19: 0 | FR19: 0 | FS19: 0 | FT19: 0 | FU19: 0 | FV19: 0 | FW19: 0 | FX19: 0
A20: o_sale_IC | B20: PRODUCT | C20: Industrial | D20: OEM | E20: [None] | F20: Sales IC | G20: -4664.2341 | H20: 0 | I20: -22183.963 | J20: 2707.7623 | K20: 0 | L20: 0 | M20: 0 | N20: 0 | O20: 0 | P20: 0 | Q20: 0 | R20: 0 | S20: 0 | T20: 0 | U20: 0 | V20: 0 | W20: 0 | X20: 0 | Y20: 0 | Z20: 0 | AA20: 0 | AB20: 0 | AC20: 0 | AD20: 0 | AE20: -57.36 | AF20: 0 | AG20: 0 | AH20: 0 | AI20: 0 | AJ20: 0 | AK20: 0 | AL20: 0 | AM20: -186768.21 | AN20: 18333.086 | AO20: -158838.63 | AP20: 0 | AQ20: 0 | AR20: 0 | AS20: 0 | AT20: 0 | AU20: 0 | AV20: 0 | AW20: 0 | AX20: 0 | AY20: 0 | AZ20: 0 | BA20: 0 | BB20: 0 | BC20: 0 | BD20: 0 | BE20: 0 | BF20: 0 | BG20: -0.76028 | BH20: 0 | BI20: 0 | BJ20: 0 | BK20: -2823.7556 | BL20: 253.6452 | BM20: 0 | BN20: 0 | BO20: 0 | BP20: 0 | BQ20: 0 | BR20: 0 | BS20: 0 | BT20: 0 | BU20: 0 | BV20: 0 | BW20: 0 | BX20: 0 | BY20: 0 | BZ20: 0 | CA20: 3.66663 | CB20: 0 | CC20: 0 | CD20: 0 | CE20: 0 | CF20: 0 | CG20: -614839.21 | CH20: 57174.061 | CI20: -0.532 | CJ20: 0 | CK20: 0 | CL20: 0 | CM20: -10235.272 | CN20: 1116.8918 | CO20: 0 | CP20: 0 | CQ20: 0 | CR20: 0 | CS20: 0 | CT20: 0 | CU20: 0 | CV20: 0 | CW20: 0 | CX20: 0 | CY20: 0 | CZ20: 0 | DA20: 0 | DB20: 0 | DC20: 0 | DD20: 0 | DE20: -7287.1672 | DF20: 937.09991 | DG20: 0 | DH20: 0 | DI20: 0 | DJ20: 0 | DK20: 0 | DL20: 0 | DM20: 0 | DN20: 0 | DO20: 0 | DP20: 0 | DQ20: 0 | DR20: 0 | DS20: 0 | DT20: 0 | DU20: 0 | DV20: 0 | DW20: 0 | DX20: 0 | DY20: 0 | DZ20: 0 | EA20: -20350.694 | EB20: 2040.0134 | EC20: 0 | ED20: 0 | EE20: 0 | EF20: 0 | EG20: 0 | EH20: 0 | EI20: 0 | EJ20: 0 | EK20: 0 | EL20: 0 | EM20: -4.92436 | EN20: 0 | EO20: 0 | EP20: 0 | EQ20: 0 | ER20: 0 | ES20: 0 | ET20: 0 | EU20: 0 | EV20: 0 | EW20: 0 | EX20: 0 | EY20: 0 | EZ20: 0 | FA20: 0 | FB20: 0 | FC20: 0 | FD20: 0 | FE20: 0 | FF20: 0 | FG20: 0 | FH20: 0 | FI20: 0 | FJ20: 0 | FK20: 0 | FL20: 0 | FM20: 0 | FN20: 0 | FO20: 0 | FP20: 0 | FQ20: 0 | FR20: 0 | FS20: 0 | FT20: 0 | FU20: 0 | FV20: 0 | FW20: 0 | FX20: 0
A21: o_sale_IC | B21: PRODUCT | C21: Industrial | D21: T&L | E21: [None] | F21: Sales IC | G21: 0 | H21: 0 | I21: -20460.582 | J21: 634.47544 | K21: 0 | L21: 0 | M21: 0 | N21: 0 | O21: 0 | P21: 0 | Q21: 0 | R21: 0 | S21: 0 | T21: 0 | U21: 0 | V21: 0 | W21: 0 | X21: 0 | Y21: 0 | Z21: 0 | AA21: 0 | AB21: 0 | AC21: 0 | AD21: 0 | AE21: 0 | AF21: 0 | AG21: 0 | AH21: 0 | AI21: 0 | AJ21: 0 | AK21: 0 | AL21: 0 | AM21: -20116.067 | AN21: 809.0604 | AO21: 0 | AP21: 0 | AQ21: 0 | AR21: 0 | AS21: 0 | AT21: 0 | AU21: 0 | AV21: 0 | AW21: 0 | AX21: 0 | AY21: 0 | AZ21: 0 | BA21: 0 | BB21: 0 | BC21: 0 | BD21: 0 | BE21: 0 | BF21: 0 | BG21: 0 | BH21: 0 | BI21: -146878.26 | BJ21: 10777.635 | BK21: -49.87114 | BL21: 47.60427 | BM21: 0 | BN21: 0 | BO21: 0 | BP21: 0 | BQ21: 0 | BR21: 0 | BS21: 0 | BT21: 0 | BU21: 0 | BV21: 0 | BW21: 0 | BX21: 0 | BY21: 0 | BZ21: 0 | CA21: 0 | CB21: 0 | CC21: 0 | CD21: 0 | CE21: 0 | CF21: 0 | CG21: -37459.868 | CH21: 1302.8523 | CI21: 0 | CJ21: 0 | CK21: 0 | CL21: 0 | CM21: 0 | CN21: 0 | CO21: 0 | CP21: 0 | CQ21: 0 | CR21: 0 | CS21: 0 | CT21: 0 | CU21: 0 | CV21: 0 | CW21: 0 | CX21: 0 | CY21: 0 | CZ21: 0 | DA21: 0 | DB21: 0 | DC21: 0 | DD21: 0 | DE21: 0 | DF21: 0 | DG21: 0 | DH21: 0 | DI21: 0 | DJ21: 0 | DK21: 0 | DL21: 0 | DM21: 0 | DN21: 0 | DO21: 0 | DP21: 0 | DQ21: 0 | DR21: 0 | DS21: 0 | DT21: 0 | DU21: 0 | DV21: 0 | DW21: 0 | DX21: 0 | DY21: 0 | DZ21: 0 | EA21: -1854.5094 | EB21: 140.07846 | EC21: 0 | ED21: 0 | EE21: 0 | EF21: 0 | EG21: 0 | EH21: 0 | EI21: 0 | EJ21: 0 | EK21: 0 | EL21: 0 | EM21: -3805.9747 | EN21: 456.24624 | EO21: 0 | EP21: 0 | EQ21: 0 | ER21: 0 | ES21: 0 | ET21: 0 | EU21: 0 | EV21: 0 | EW21: 0 | EX21: 0 | EY21: 0 | EZ21: 0 | FA21: 0 | FB21: 0 | FC21: 0 | FD21: 0 | FE21: -2669.3144 | FF21: 268.82993 | FG21: 0 | FH21: 0 | FI21: 0 | FJ21: 0 | FK21: 0 | FL21: 0 | FM21: 0 | FN21: 0 | FO21: 0 | FP21: 0 | FQ21: 0 | FR21: 0 | FS21: 0 | FT21: 0 | FU21: 0 | FV21: 0 | FW21: 0 | FX21: 0
A22: o_sale_IC | B22: PRODUCT | C22: Industrial | D22: Vehicle | E22: [None] | F22: Sales IC | G22: -24566.63 | H22: 3153.1795 | I22: -3524.7326 | J22: -7.1054274e-15 | K22: 0 | L22: 0 | M22: 0 | N22: 0 | O22: 0 | P22: 0 | Q22: 0 | R22: 0 | S22: 0 | T22: 0 | U22: 0 | V22: 0 | W22: 0 | X22: 0 | Y22: 0 | Z22: 0 | AA22: -19.28183 | AB22: -99.98625 | AC22: 0 | AD22: 71.92686 | AE22: 0 | AF22: 0 | AG22: 0 | AH22: 0 | AI22: 0 | AJ22: 0 | AK22: 0 | AL22: 0 | AM22: -47234.839 | AN22: 4654.6835 | AO22: -98979.179 | AP22: 0 | AQ22: 0 | AR22: 0 | AS22: 0 | AT22: 0 | AU22: 0 | AV22: 0 | AW22: 0 | AX22: 0 | AY22: 0 | AZ22: 0 | BA22: 0 | BB22: 0 | BC22: 0 | BD22: 0 | BE22: 0 | BF22: 0 | BG22: 0 | BH22: 0 | BI22: 0 | BJ22: 0 | BK22: 0 | BL22: 0 | BM22: 0 | BN22: 0 | BO22: 0 | BP22: 0 | BQ22: 0 | BR22: 0 | BS22: 0 | BT22: 0 | BU22: 0 | BV22: 0 | BW22: 0 | BX22: 0 | BY22: 0 | BZ22: 0 | CA22: 0 | CB22: 0 | CC22: 0 | CD22: 0 | CE22: 0 | CF22: 0 | CG22: -339173.81 | CH22: 37981.789 | CI22: 0 | CJ22: 0 | CK22: 0 | CL22: 0 | CM22: 0 | CN22: 0 | CO22: 0 | CP22: 0 | CQ22: 0 | CR22: 0 | CS22: 0 | CT22: 0 | CU22: 0 | CV22: 0 | CW22: 0 | CX22: 0 | CY22: 0 | CZ22: 0 | DA22: 0 | DB22: 0 | DC22: 0 | DD22: 0 | DE22: 0 | DF22: 0 | DG22: 0 | DH22: 0 | DI22: 0 | DJ22: 0 | DK22: 0 | DL22: 0 | DM22: 0 | DN22: 0 | DO22: 0 | DP22: 0 | DQ22: 0 | DR22: 0 | DS22: 0 | DT22: 0 | DU22: 0 | DV22: 0 | DW22: 0 | DX22: 0 | DY22: 0 | DZ22: 0 | EA22: -1102.5489 | EB22: 99.26308 | EC22: 0 | ED22: 0 | EE22: 0 | EF22: 0 | EG22: 0 | EH22: 0 | EI22: 0 | EJ22: 0 | EK22: 0 | EL22: 0 | EM22: 0 | EN22: 0 | EO22: 0 | EP22: 0 | EQ22: 0 | ER22: 0 | ES22: 0 | ET22: 0 | EU22: 0 | EV22: 0 | EW22: 0 | EX22: 0 | EY22: 0 | EZ22: 0 | FA22: 0 | FB22: 0 | FC22: 0 | FD22: 0 | FE22: 0 | FF22: 0 | FG22: 0 | FH22: 0 | FI22: 0 | FJ22: 0 | FK22: 0 | FL22: 0 | FM22: 0 | FN22: 0 | FO22: 0 | FP22: 0 | FQ22: 0 | FR22: 0 | FS22: 0 | FT22: 0 | FU22: 0 | FV22: 0 | FW22: 0 | FX22: 0
A23: o_sale_IC | B23: PRODUCT | C23: Industrial | D23: AS | E23: [None] | F23: Sales IC | G23: 0 | H23: 0 | I23: 0 | J23: 0 | K23: 0 | L23: 0 | M23: 0 | N23: 0 | O23: 0 | P23: 0 | Q23: 0 | R23: 0 | S23: 0 | T23: 0 | U23: 0 | V23: 0 | W23: 0 | X23: 0 | Y23: 0 | Z23: 0 | AA23: 0 | AB23: 0 | AC23: 0 | AD23: 0 | AE23: 0 | AF23: 0 | AG23: 0 | AH23: 0 | AI23: 0 | AJ23: 0 | AK23: 0 | AL23: 0 | AM23: 0 | AN23: 0 | AO23: 0 | AP23: 0 | AQ23: 0 | AR23: 0 | AS23: 0 | AT23: 0 | AU23: 0 | AV23: 0 | AW23: 0 | AX23: 0 | AY23: 0 | AZ23: 0 | BA23: 0 | BB23: 0 | BC23: 0 | BD23: 0 | BE23: 0 | BF23: 0 | BG23: 0 | BH23: 0 | BI23: 0 | BJ23: 0 | BK23: 0 | BL23: 0 | BM23: 0 | BN23: 0 | BO23: 0 | BP23: 0 | BQ23: 0 | BR23: 0 | BS23: 0 | BT23: 0 | BU23: 0 | BV23: 0 | BW23: 0 | BX23: 0 | BY23: 0 | BZ23: 0 | CA23: 0 | CB23: 0 | CC23: 0 | CD23: 0 | CE23: 0 | CF23: 0 | CG23: -93767.384 | CH23: 8286.2652 | CI23: 0 | CJ23: 0 | CK23: 0 | CL23: 0 | CM23: 0 | CN23: 0 | CO23: 0 | CP23: 0 | CQ23: 0 | CR23: 0 | CS23: 0 | CT23: 0 | CU23: 0 | CV23: 0 | CW23: 0 | CX23: 0 | CY23: 0 | CZ23: 0 | DA23: 0 | DB23: 0 | DC23: 0 | DD23: 0 | DE23: 0 | DF23: 0 | DG23: 0 | DH23: 0 | DI23: 0 | DJ23: 0 | DK23: 0 | DL23: 0 | DM23: 0 | DN23: 0 | DO23: 0 | DP23: 0 | DQ23: 0 | DR23: 0 | DS23: 0 | DT23: 0 | DU23: 0 | DV23: 0 | DW23: 0 | DX23: 0 | DY23: 0 | DZ23: 0 | EA23: 0 | EB23: 0 | EC23: 0 | ED23: 0 | EE23: 0 | EF23: 0 | EG23: 0 | EH23: 0 | EI23: 0 | EJ23: 0 | EK23: 0 | EL23: 0 | EM23: 0 | EN23: 0 | EO23: 0 | EP23: 0 | EQ23: 0 | ER23: 0 | ES23: 0 | ET23: 0 | EU23: 0 | EV23: 0 | EW23: 0 | EX23: 0 | EY23: 0 | EZ23: 0 | FA23: 0 | FB23: 0 | FC23: 0 | FD23: 0 | FE23: 0 | FF23: 0 | FG23: 0 | FH23: 0 | FI23: 0 | FJ23: 0 | FK23: 0 | FL23: 0 | FM23: 0 | FN23: 0 | FO23: 0 | FP23: 0 | FQ23: 0 | FR23: 0 | FS23: 0 | FT23: 0 | FU23: 0 | FV23: 0 | FW23: 0 | FX23: 0
... A41: o_sale_IC | B41: SERVICE | C41: Retail | D41: Retail | E41: [None] | F41: Sales IC | G41: 0 | H41: 0 | I41: -2840.9342 | J41: 428.41287 | K41: 0 | L41: 0 | M41: 0 | N41: 0 | O41: 0 | P41: 0 | Q41: 0 | R41: 0 | S41: -3.00668 | T41: 0.245 | U41: 7.87237 | V41: -0.47441 | W41: 0 | X41: 0 | Y41: -3.9027835 | Z41: 0 | AA41: 0 | AB41: 0 | AC41: -2.90945 | AD41: 0 | AE41: -1.06099 | AF41: 0.03726 | AG41: 0 | AH41: 0 | AI41: 0 | AJ41: 0 | AK41: 0 | AL41: 0 | AM41: -23782.852 | AN41: 270.57888 | AO41: 0 | AP41: 0 | AQ41: 0 | AR41: 0 | AS41: 0 | AT41: 0 | AU41: 0 | AV41: 0 | AW41: 0 | AX41: 0 | AY41: 0 | AZ41: 0 | BA41: 0 | BB41: 0 | BC41: 0 | BD41: 0 | BE41: 0 | BF41: 0 | BG41: 0 | BH41: 0 | BI41: 0 | BJ41: 0 | BK41: -261.6336 | BL41: 39.17304 | BM41: 0 | BN41: 0 | BO41: 0 | BP41: 0 | BQ41: 0 | BR41: 0 | BS41: 0 | BT41: 0 | BU41: 0 | BV41: 0 | BW41: 0 | BX41: 0 | BY41: 0 | BZ41: 0 | CA41: 0 | CB41: 0 | CC41: 0 | CD41: 0 | CE41: 0 | CF41: 0 | CG41: -2222.6689 | CH41: 215.84587 | CI41: 0 | CJ41: 0 | CK41: 0 | CL41: 0 | CM41: -0.6589 | CN41: 0 | CO41: 0 | CP41: 0 | CQ41: 0 | CR41: 0 | CS41: 0 | CT41: 0 | CU41: 0 | CV41: 0 | CW41: 0 | CX41: 0 | CY41: 0 | CZ41: 0 | DA41: 0 | DB41: 0 | DC41: 0 | DD41: 0 | DE41: 0 | DF41: 0 | DG41: 0 | DH41: 0 | DI41: 0 | DJ41: 0 | DK41: 0 | DL41: 0 | DM41: 0 | DN41: 0 | DO41: 0 | DP41: 0 | DQ41: 0 | DR41: 0 | DS41: 0 | DT41: 0 | DU41: 0 | DV41: 0 | DW41: 0 | DX41: 0 | DY41: 0 | DZ41: 0 | EA41: -1987.6382 | EB41: 212.07352 | EC41: 0 | ED41: 0 | EE41: 0 | EF41: 0 | EG41: 0 | EH41: 0 | EI41: 0 | EJ41: 0 | EK41: 0 | EL41: 0 | EM41: -0.22349 | EN41: 0 | EO41: 0 | EP41: 0 | EQ41: 0 | ER41: 0 | ES41: 0 | ET41: 0 | EU41: 0 | EV41: 0 | EW41: 0 | EX41: 0 | EY41: 0 | EZ41: 0 | FA41: 0 | FB41: 0 | FC41: 0 | FD41: 0 | FE41: 0 | FF41: 0 | FG41: 0 | FH41: 0 | FI41: 0 | FJ41: 0 | FK41: 0 | FL41: 0 | FM41: 0 | FN41: 0 | FO41: -3.298 | FP41: 0 | FQ41: -0.02866 | FR41: 0.02404 | FS41: 0 | FT41: 0 | FU41: 0 | FV41: 0 | FW41: 0 | FX41: 0

Sheet Currency
B1: Unit Name | C1: Unit Number | D1: Submit to Unit | E1: Currency
A2: 1 | B2: MT-A | C2: GMC_MOCentral_EU.2160 | D2: GMC_MOCentral_EU.2160 | E2: EUR
A3: 2 | B3: MT-CH | C3: GMC_MOCentral_EU.2175 | D3: GMC_MOCentral_EU.2175 | E3: CHF
A4: 3 | B4: MT-D | C4: GMC_MOCentral_EU.2090 | D4: GMC_MOCentral_EU.2090 | E4: EUR
A5: 4 | B5: MT-MEC ex-UA | C5: 299_USD.299_EUR | D5: 299_EUR.2099 | E5: EUR
A6: 5 | B6: MT-UA | C6: GMC_MT_UA.2511_USD | D6: GMC_MT_UA.2511_USD | E6: USD
A7: 6 | B7: MT-TR | C7: 211_EUR.2111 | D7: 211_EUR.2111 | E7: EUR
A8: 7 | B8: MT-Nordic | C8: GMC_NRegion_EU.232 | D8: 232.2032 | E8: SEK
A9: 8 | B9: MT-UK | C9: GMC_EURO_MO.2072 | D9: GMC_EURO_MO.2072 | E9: GBP
A10: 9 | B10: MT-F | C10: GMC_MT_F.2140 | D10: GMC_MT_F.2140 | E10: EUR
A11: 10 | B11: MT-BNL | C11: GMC_EURO_MO.271 | D11: 270.2130 | E11: EUR
A12: 11 | B12: MT-B | C12: 270.2130 | D12: 270.2130 | E12: EUR
A13: 12 | B13: MT-NL | C13: 270.3000 | D13: 270.3000 | E13: EUR
... A19: 18 | B19: MT-SI | C19: GMC_SRegion_EU_MX.2060 | D19: GMC_SRegion_EU_MX.2060 | E19: USD
A20: 19
A21: 20 | B21: MT-CDN | C21: 355.1012 | D21: 355.1012 | E21: CAD
A22: 21 | B22: MTMO-US | C22: 355.1021 | D22: 355.1021 | E22: USD
A23: 22
A24: 23 | B24: AP-HUB | C24: AP_Hub.5011 | D24: AP_Hub.5011 | E24: CNY
A25: 24 | B25: MTMO-China (CNY) | C25: 511_USD.511 | D25: 501SH.5014 | E25: CNY
A26: 25 | B26: MTPOChina (CNY) | C26: GMC_MOPOChina.515 | D26: 505CZ.5053 | E26: CNY
A27: 26 | B27: MTGF-AP | C27: 929.5085 | D27: 929.5085 | E27: CNY
A28: 27
A29: 28 | B29: MT-JP | C29: GMC_ASIA.5031 | D29: GMC_ASIA.5031 | E29: JPY
A30: 29 | B30: MT-MY | C30: 562.5161 | D30: 562.5161 | E30: MYR
A31: 30 | B31: MTAP-SER | C31: 562.5162 | D31: 562.5162 | E31: MYR
A32: 31 | B32: MT-SG | C32: GMC_SG_ID_SGD.5181 | D32: GMC_SG_ID_SGD.5181 | E32: SGD
A33: 32 | B33: MT-ID | C33: Geo_ID.5183 | D33: Geo_ID.5183 | E33: IDR
A34: 33 | B34: MT-TH | C34: GMC_TH_VN_THB.5191 | D34: GMC_TH_VN_THB.5191 | E34: THB
A35: 34 | B35: MT-VN | C35: GMC_TH_VN_THB.5193 | D35: GMC_TH_VN_THB.5193 | E35: VND
A36: 35 | B36: MT-TW | C36: GMC_ASIA.5025 | D36: GMC_ASIA.5025 | E36: TWD
A37: 36 | B37: MT-KR | C37: GMC_ASIA.5141 | D37: GMC_ASIA.5141 | E37: KRW
A38: 37 | B38: MT-AUS/NZ | C38: GMC_ASIA.524 | D38: 524.5231 | E38: AUD
A39: 38 | B39: MTIN | C39: GMC_ASIA.5151 | D39: GMC_ASIA.5151 | E39: INR
A40: 39
A41: 40 | B41: WeighTec | C41: GMC_MTIC_LAB_CHF.2181 | D41: GMC_MTIC_LAB_CHF.2181 | E41: CHF
A42: 41 | B42: MTANA | C42: 295.2186 | D42: 295.2186 | E42: CHF
A43: 42 | B43: TRUS | C43: GMC_Lab.1024 | D43: GMC_Lab.1024 | E43: USD
A44: 43 | B44: OHUS | C44: GMC_Lab.1027 | D44: GMC_Lab.1027 | E44: USD
A45: 44 | B45: India IMSG | C45: GMC_Lab.5155 | D45: GMC_Lab.5155 | E45: INR
...
